<mujoco model="humanoid">
  <compiler coordinate="local" />
  <default>
    <joint damping="0.0" armature="0.01" stiffness="0.0" limited="true" />
    <geom conaffinity="1" condim="3" contype="7" margin="0.001" rgba="0.8 0.6 .4 1" />
  </default>
  <asset>
    <texture type="skybox" builtin="gradient" rgb1=".4 .5 .6" rgb2="0 0 0" width="100" height="100" />
    <texture builtin="flat" height="1278" mark="cross" markrgb="1 1 1" name="texgeom" random="0.01" rgb1="0.8 0.6 0.4" rgb2="0.8 0.6 0.4" type="cube" width="127" />
    <texture builtin="checker" height="100" name="texplane" rgb1="0 0 0" rgb2="0.8 0.8 0.8" type="2d" width="100" />
    <material name="MatPlane" reflectance="0.5" shininess="1" specular="1" texrepeat="60 60" texture="texplane" />
    <material name="geom" texture="texgeom" texuniform="true" />
  </asset>
  <worldbody>
    <light cutoff="100" diffuse="1 1 1" dir="-0 0 -1.3" directional="true" exponent="1" pos="0 0 1.3" specular=".1 .1 .1" />
    <geom conaffinity="1" condim="3" name="floor" pos="0 0 0" rgba="0.8 0.9 0.8 1" size="100 100 .2" type="plane" material="MatPlane" />
    <body name="Pelvis" pos="-0.0021 -0.2184 0.026">
      <freejoint name="Pelvis" />
      <geom type="box" pos="-0.0067 0.0001 -0.0108" size="0.0775 0.1028 0.0697" quat="1.0000 0.0000 0.0000 0.0000" density="1000" />
      <body name="L_Hip" pos="-0.0071 0.0667 -0.088">
        <joint name="L_Hip_x" type="hinge" pos="0 0 0" axis="1 0 0" stiffness="800" damping="80" armature="0.02" range="-180.0000 180.0000" />
        <joint name="L_Hip_y" type="hinge" pos="0 0 0" axis="0 1 0" stiffness="800" damping="80" armature="0.02" range="-180.0000 180.0000" />
        <joint name="L_Hip_z" type="hinge" pos="0 0 0" axis="0 0 1" stiffness="800" damping="80" armature="0.02" range="-180.0000 180.0000" />
        <geom type="capsule" contype="1" conaffinity="1" density="2040.816327" fromto="-0.0005 0.0069 -0.0734 -0.0018 0.0277 -0.2937" size="0.059" />
        <body name="L_Knee" pos="-0.0023 0.0346 -0.3672">
          <joint name="L_Knee_x" type="hinge" pos="0 0 0" axis="1 0 0" stiffness="800" damping="80" armature="0.02" range="-180.0000 180.0000" />
          <joint name="L_Knee_y" type="hinge" pos="0 0 0" axis="0 1 0" stiffness="800" damping="80" armature="0.02" range="-180.0000 180.0000" />
          <joint name="L_Knee_z" type="hinge" pos="0 0 0" axis="0 0 1" stiffness="800" damping="80" armature="0.02" range="-180.0000 180.0000" />
          <geom type="capsule" contype="1" conaffinity="1" density="1234.567901" fromto="-0.0083 -0.0026 -0.0774 -0.0331 -0.0105 -0.3095" size="0.052" />
          <body name="L_Ankle" pos="-0.0414 -0.0131 -0.3869">
            <joint name="L_Ankle_x" type="hinge" pos="0 0 0" axis="1 0 0" stiffness="800" damping="80" armature="0.02" range="-180.0000 180.0000" />
            <joint name="L_Ankle_y" type="hinge" pos="0 0 0" axis="0 1 0" stiffness="800" damping="80" armature="0.02" range="-180.0000 180.0000" />
            <joint name="L_Ankle_z" type="hinge" pos="0 0 0" axis="0 0 1" stiffness="800" damping="80" armature="0.02" range="-180.0000 180.0000" />
            <geom type="box" pos="0.0240 0.0231 -0.0234" size="0.0827 0.047 0.045" quat="1.0000 0.0000 0.0000 0.0000" density="1000" />
            <body name="L_Toe" pos="0.1165 0.0259 -0.0544">
              <joint name="L_Toe_x" type="hinge" pos="0 0 0" axis="1 0 0" stiffness="500" damping="50" armature="0.02" range="-180.0000 180.0000" />
              <joint name="L_Toe_y" type="hinge" pos="0 0 0" axis="0 1 0" stiffness="500" damping="50" armature="0.02" range="-180.0000 180.0000" />
              <joint name="L_Toe_z" type="hinge" pos="0 0 0" axis="0 0 1" stiffness="500" damping="50" armature="0.02" range="-180.0000 180.0000" />
              <geom type="box" pos="0.0243 -0.0028 0.0056" size="0.0482 0.0466 0.0196" quat="1.0000 0.0000 0.0000 0.0000" density="1000" />
            </body>
          </body>
        </body>
      </body>
      <body name="R_Hip" pos="-0.0049 -0.0649 -0.0871">
        <joint name="R_Hip_x" type="hinge" pos="0 0 0" axis="1 0 0" stiffness="800" damping="80" armature="0.02" range="-180.0000 180.0000" />
        <joint name="R_Hip_y" type="hinge" pos="0 0 0" axis="0 1 0" stiffness="800" damping="80" armature="0.02" range="-180.0000 180.0000" />
        <joint name="R_Hip_z" type="hinge" pos="0 0 0" axis="0 0 1" stiffness="800" damping="80" armature="0.02" range="-180.0000 180.0000" />
        <geom type="capsule" contype="1" conaffinity="1" density="2040.816327" fromto="-0.0013 -0.0076 -0.0748 -0.0052 -0.0306 -0.2992" size="0.058" />
        <body name="R_Knee" pos="-0.0065 -0.0382 -0.374">
          <joint name="R_Knee_x" type="hinge" pos="0 0 0" axis="1 0 0" stiffness="800" damping="80" armature="0.02" range="-180.0000 180.0000" />
          <joint name="R_Knee_y" type="hinge" pos="0 0 0" axis="0 1 0" stiffness="800" damping="80" armature="0.02" range="-180.0000 180.0000" />
          <joint name="R_Knee_z" type="hinge" pos="0 0 0" axis="0 0 1" stiffness="800" damping="80" armature="0.02" range="-180.0000 180.0000" />
          <geom type="capsule" contype="1" conaffinity="1" density="1234.567901" fromto="-0.0080 0.0031 -0.0774 -0.0319 0.0122 -0.3097" size="0.0522" />
          <body name="R_Ankle" pos="-0.0398 0.0153 -0.3871">
            <joint name="R_Ankle_x" type="hinge" pos="0 0 0" axis="1 0 0" stiffness="800" damping="80" armature="0.02" range="-180.0000 180.0000" />
            <joint name="R_Ankle_y" type="hinge" pos="0 0 0" axis="0 1 0" stiffness="800" damping="80" armature="0.02" range="-180.0000 180.0000" />
            <joint name="R_Ankle_z" type="hinge" pos="0 0 0" axis="0 0 1" stiffness="800" damping="80" armature="0.02" range="-180.0000 180.0000" />
            <geom type="box" pos="0.0253 -0.0195 -0.0171" size="0.0842 0.047 0.0465" quat="1.0000 0.0000 0.0000 0.0000" density="1000" />
            <body name="R_Toe" pos="0.1202 -0.0234 -0.0471">
              <joint name="R_Toe_x" type="hinge" pos="0 0 0" axis="1 0 0" stiffness="500" damping="50" armature="0.02" range="-180.0000 180.0000" />
              <joint name="R_Toe_y" type="hinge" pos="0 0 0" axis="0 1 0" stiffness="500" damping="50" armature="0.02" range="-180.0000 180.0000" />
              <joint name="R_Toe_z" type="hinge" pos="0 0 0" axis="0 0 1" stiffness="500" damping="50" armature="0.02" range="-180.0000 180.0000" />
              <geom type="box" pos="0.0228 0.0039 0.0044" size="0.0484 0.0466 0.0209" quat="1.0000 0.0000 0.0000 0.0000" density="1000" />
            </body>
          </body>
        </body>
      </body>
      <body name="Torso" pos="-0.0245 -0.0025 0.105">
        <joint name="Torso_x" type="hinge" pos="0 0 0" axis="1 0 0" stiffness="1000" damping="100" armature="0.02" range="-180.0000 180.0000" />
        <joint name="Torso_y" type="hinge" pos="0 0 0" axis="0 1 0" stiffness="1000" damping="100" armature="0.02" range="-180.0000 180.0000" />
        <joint name="Torso_z" type="hinge" pos="0 0 0" axis="0 0 1" stiffness="1000" damping="100" armature="0.02" range="-180.0000 180.0000" />
        <geom type="capsule" contype="1" conaffinity="1" density="2040.816327" fromto="0.0008 0.0025 0.0598 0.0010 0.0030 0.0731" size="0.0734" />
        <body name="Spine" pos="0.0017 0.0055 0.1328">
          <joint name="Spine_x" type="hinge" pos="0 0 0" axis="1 0 0" stiffness="1000" damping="100" armature="0.02" range="-180.0000 180.0000" />
          <joint name="Spine_y" type="hinge" pos="0 0 0" axis="0 1 0" stiffness="1000" damping="100" armature="0.02" range="-180.0000 180.0000" />
          <joint name="Spine_z" type="hinge" pos="0 0 0" axis="0 0 1" stiffness="1000" damping="100" armature="0.02" range="-180.0000 180.0000" />
          <geom type="capsule" contype="1" conaffinity="1" density="2040.816327" fromto="0.0104 0.0007 0.0232 0.0127 0.0009 0.0284" size="0.0723" />
          <body name="Chest" pos="0.0231 0.0016 0.0516">
            <joint name="Chest_x" type="hinge" pos="0 0 0" axis="1 0 0" stiffness="1000" damping="100" armature="0.02" range="-180.0000 180.0000" />
            <joint name="Chest_y" type="hinge" pos="0 0 0" axis="0 1 0" stiffness="1000" damping="100" armature="0.02" range="-180.0000 180.0000" />
            <joint name="Chest_z" type="hinge" pos="0 0 0" axis="0 0 1" stiffness="1000" damping="100" armature="0.02" range="-180.0000 180.0000" />
            <geom type="capsule" contype="1" conaffinity="1" density="2040.816327" fromto="-0.0166 -0.0010 0.0666 -0.0203 -0.0012 0.0814" size="0.0967" />
            <body name="Neck" pos="-0.0415 -0.0034 0.2093">
              <joint name="Neck_x" type="hinge" pos="0 0 0" axis="1 0 0" stiffness="500" damping="50" armature="0.02" range="-180.0000 180.0000" />
              <joint name="Neck_y" type="hinge" pos="0 0 0" axis="0 1 0" stiffness="500" damping="50" armature="0.02" range="-180.0000 180.0000" />
              <joint name="Neck_z" type="hinge" pos="0 0 0" axis="0 0 1" stiffness="500" damping="50" armature="0.02" range="-180.0000 180.0000" />
              <geom type="capsule" contype="1" conaffinity="1" density="1000" fromto="0.0100 0.0011 0.0130 0.0401 0.0044 0.0519" size="0.0427" />
              <body name="Head" pos="0.0501 0.0055 0.0649">
                <joint name="Head_x" type="hinge" pos="0 0 0" axis="1 0 0" stiffness="500" damping="50" armature="0.02" range="-180.0000 180.0000" />
                <joint name="Head_y" type="hinge" pos="0 0 0" axis="0 1 0" stiffness="500" damping="50" armature="0.02" range="-180.0000 180.0000" />
                <joint name="Head_z" type="hinge" pos="0 0 0" axis="0 0 1" stiffness="500" damping="50" armature="0.02" range="-180.0000 180.0000" />
                <geom type="box" pos="-0.0110 -0.0042 0.0863" size="0.0746 0.0595 0.1133" quat="1.0000 0.0000 0.0000 0.0000" density="1000" />
                
              </body>
            </body>
            <body name="L_Thorax" pos="-0.0325 0.0773 0.1187">
              <joint name="L_Thorax_x" type="hinge" pos="0 0 0" axis="1 0 0" stiffness="500" damping="50" armature="0.02" range="-180.0000 180.0000" />
              <joint name="L_Thorax_y" type="hinge" pos="0 0 0" axis="0 1 0" stiffness="500" damping="50" armature="0.02" range="-180.0000 180.0000" />
              <joint name="L_Thorax_z" type="hinge" pos="0 0 0" axis="0 0 1" stiffness="500" damping="50" armature="0.02" range="-180.0000 180.0000" />
              <geom type="capsule" contype="1" conaffinity="1" density="1000" fromto="-0.0016 0.0181 0.0060 -0.0066 0.0724 0.0240" size="0.0506" />
              <body name="L_Shoulder" pos="-0.0082 0.0905 0.0299">
                <joint name="L_Shoulder_x" type="hinge" pos="0 0 0" axis="1 0 0" stiffness="500" damping="50" armature="0.02" range="-720.0000 720.0000" />
                <joint name="L_Shoulder_y" type="hinge" pos="0 0 0" axis="0 1 0" stiffness="500" damping="50" armature="0.02" range="-720.0000 720.0000" />
                <joint name="L_Shoulder_z" type="hinge" pos="0 0 0" axis="0 0 1" stiffness="500" damping="50" armature="0.02" range="-720.0000 720.0000" />
                <geom type="capsule" contype="1" conaffinity="1" density="1000" fromto="-0.0052 0.0507 -0.0024 -0.0207 0.2027 -0.0098" size="0.0497" />
                <body name="L_Elbow" pos="-0.0259 0.2534 -0.0122">
                  <joint name="L_Elbow_x" type="hinge" pos="0 0 0" axis="1 0 0" stiffness="500" damping="50" armature="0.02" range="-720.0000 720.0000" />
                  <joint name="L_Elbow_y" type="hinge" pos="0 0 0" axis="0 1 0" stiffness="500" damping="50" armature="0.02" range="-720.0000 720.0000" />
                  <joint name="L_Elbow_z" type="hinge" pos="0 0 0" axis="0 0 1" stiffness="500" damping="50" armature="0.02" range="-720.0000 720.0000" />
                  <geom type="capsule" contype="1" conaffinity="1" density="1000" fromto="-0.0003 0.0486 0.0017 -0.0012 0.1944 0.0067" size="0.0392" />
                  <body name="L_Wrist" pos="-0.0015 0.243 0.0084">
                    <joint name="L_Wrist_x" type="hinge" pos="0 0 0" axis="1 0 0" stiffness="300" damping="30" armature="0.02" range="-180.0000 180.0000" />
                    <joint name="L_Wrist_y" type="hinge" pos="0 0 0" axis="0 1 0" stiffness="300" damping="30" armature="0.02" range="-180.0000 180.0000" />
                    <joint name="L_Wrist_z" type="hinge" pos="0 0 0" axis="0 0 1" stiffness="300" damping="30" armature="0.02" range="-180.0000 180.0000" />
                    <geom type="capsule" contype="1" conaffinity="1" density="1000" fromto="-0.0029 0.0163 -0.0016 -0.0116 0.0654 -0.0064" size="0.0309" />
                    <body name="L_Hand" pos="-0.0145 0.0817 -0.008">
                      <joint name="L_Hand_x" type="hinge" pos="0 0 0" axis="1 0 0" stiffness="300" damping="30" armature="0.02" range="-180.0000 180.0000" />
                      <joint name="L_Hand_y" type="hinge" pos="0 0 0" axis="0 1 0" stiffness="300" damping="30" armature="0.02" range="-180.0000 180.0000" />
                      <joint name="L_Hand_z" type="hinge" pos="0 0 0" axis="0 0 1" stiffness="300" damping="30" armature="0.02" range="-180.0000 180.0000" />
                      <geom type="box" pos="-0.0056 0.0480 0.0010" size="0.0523 0.0569 0.0154" quat="1.0000 0.0000 0.0000 0.0000" density="1000" />
                    </body>
                  </body>
                </body>
              </body>
            </body>
            <body name="R_Thorax" pos="-0.037 -0.0805 0.1158">
              <joint name="R_Thorax_x" type="hinge" pos="0 0 0" axis="1 0 0" stiffness="500" damping="50" armature="0.02" range="-180.0000 180.0000" />
              <joint name="R_Thorax_y" type="hinge" pos="0 0 0" axis="0 1 0" stiffness="500" damping="50" armature="0.02" range="-180.0000 180.0000" />
              <joint name="R_Thorax_z" type="hinge" pos="0 0 0" axis="0 0 1" stiffness="500" damping="50" armature="0.02" range="-180.0000 180.0000" />
              <geom type="capsule" contype="1" conaffinity="1" density="1000" fromto="-0.0018 -0.0190 0.0064 -0.0073 -0.0759 0.0258" size="0.0496" />
              <body name="R_Shoulder" pos="-0.0091 -0.0949 0.0322">
                <joint name="R_Shoulder_x" type="hinge" pos="0 0 0" axis="1 0 0" stiffness="500" damping="50" armature="0.02" range="-720.0000 720.0000" />
                <joint name="R_Shoulder_y" type="hinge" pos="0 0 0" axis="0 1 0" stiffness="500" damping="50" armature="0.02" range="-720.0000 720.0000" />
                <joint name="R_Shoulder_z" type="hinge" pos="0 0 0" axis="0 0 1" stiffness="500" damping="50" armature="0.02" range="-720.0000 720.0000" />
                <geom type="capsule" contype="1" conaffinity="1" density="1000" fromto="-0.0039 -0.0494 -0.0026 -0.0157 -0.1975 -0.0102" size="0.0511" />
                <body name="R_Elbow" pos="-0.0197 -0.2469 -0.0128">
                  <joint name="R_Elbow_x" type="hinge" pos="0 0 0" axis="1 0 0" stiffness="500" damping="50" armature="0.02" range="-720.0000 720.0000" />
                  <joint name="R_Elbow_y" type="hinge" pos="0 0 0" axis="0 1 0" stiffness="500" damping="50" armature="0.02" range="-720.0000 720.0000" />
                  <joint name="R_Elbow_z" type="hinge" pos="0 0 0" axis="0 0 1" stiffness="500" damping="50" armature="0.02" range="-720.0000 720.0000" />
                  <geom type="capsule" contype="1" conaffinity="1" density="1000" fromto="-0.0011 -0.0497 0.0014 -0.0045 -0.1987 0.0055" size="0.0394" />
                  <body name="R_Wrist" pos="-0.0057 -0.2483 0.0068">
                    <joint name="R_Wrist_x" type="hinge" pos="0 0 0" axis="1 0 0" stiffness="300" damping="30" armature="0.02" range="-180.0000 180.0000" />
                    <joint name="R_Wrist_y" type="hinge" pos="0 0 0" axis="0 1 0" stiffness="300" damping="30" armature="0.02" range="-180.0000 180.0000" />
                    <joint name="R_Wrist_z" type="hinge" pos="0 0 0" axis="0 0 1" stiffness="300" damping="30" armature="0.02" range="-180.0000 180.0000" />
                    <geom type="capsule" contype="1" conaffinity="1" density="1000" fromto="-0.0020 -0.0164 -0.0012 -0.0079 -0.0656 -0.0048" size="0.0315" />
                    <body name="R_Hand" pos="-0.0099 -0.082 -0.0059">
                      <joint name="R_Hand_x" type="hinge" pos="0 0 0" axis="1 0 0" stiffness="300" damping="30" armature="0.02" range="-180.0000 180.0000" />
                      <joint name="R_Hand_y" type="hinge" pos="0 0 0" axis="0 1 0" stiffness="300" damping="30" armature="0.02" range="-180.0000 180.0000" />
                      <joint name="R_Hand_z" type="hinge" pos="0 0 0" axis="0 0 1" stiffness="300" damping="30" armature="0.02" range="-180.0000 180.0000" />
                      <geom type="box" pos="-0.0077 -0.0448 -0.0009" size="0.0529 0.0552 0.0158" quat="1.0000 0.0000 0.0000 0.0000" density="1000" />
                    </body>
                  </body>
                </body>
              </body>
            </body>
          </body>
        </body>
      </body>
    </body>
  </worldbody>
  <actuator>
    <motor name="L_Hip_x" joint="L_Hip_x" gear="500" />
    <motor name="L_Hip_y" joint="L_Hip_y" gear="500" />
    <motor name="L_Hip_z" joint="L_Hip_z" gear="500" />
    <motor name="L_Knee_x" joint="L_Knee_x" gear="500" />
    <motor name="L_Knee_y" joint="L_Knee_y" gear="500" />
    <motor name="L_Knee_z" joint="L_Knee_z" gear="500" />
    <motor name="L_Ankle_x" joint="L_Ankle_x" gear="500" />
    <motor name="L_Ankle_y" joint="L_Ankle_y" gear="500" />
    <motor name="L_Ankle_z" joint="L_Ankle_z" gear="500" />
    <motor name="L_Toe_x" joint="L_Toe_x" gear="500" />
    <motor name="L_Toe_y" joint="L_Toe_y" gear="500" />
    <motor name="L_Toe_z" joint="L_Toe_z" gear="500" />
    <motor name="R_Hip_x" joint="R_Hip_x" gear="500" />
    <motor name="R_Hip_y" joint="R_Hip_y" gear="500" />
    <motor name="R_Hip_z" joint="R_Hip_z" gear="500" />
    <motor name="R_Knee_x" joint="R_Knee_x" gear="500" />
    <motor name="R_Knee_y" joint="R_Knee_y" gear="500" />
    <motor name="R_Knee_z" joint="R_Knee_z" gear="500" />
    <motor name="R_Ankle_x" joint="R_Ankle_x" gear="500" />
    <motor name="R_Ankle_y" joint="R_Ankle_y" gear="500" />
    <motor name="R_Ankle_z" joint="R_Ankle_z" gear="500" />
    <motor name="R_Toe_x" joint="R_Toe_x" gear="500" />
    <motor name="R_Toe_y" joint="R_Toe_y" gear="500" />
    <motor name="R_Toe_z" joint="R_Toe_z" gear="500" />
    <motor name="Torso_x" joint="Torso_x" gear="500" />
    <motor name="Torso_y" joint="Torso_y" gear="500" />
    <motor name="Torso_z" joint="Torso_z" gear="500" />
    <motor name="Spine_x" joint="Spine_x" gear="500" />
    <motor name="Spine_y" joint="Spine_y" gear="500" />
    <motor name="Spine_z" joint="Spine_z" gear="500" />
    <motor name="Chest_x" joint="Chest_x" gear="500" />
    <motor name="Chest_y" joint="Chest_y" gear="500" />
    <motor name="Chest_z" joint="Chest_z" gear="500" />
    <motor name="Neck_x" joint="Neck_x" gear="500" />
    <motor name="Neck_y" joint="Neck_y" gear="500" />
    <motor name="Neck_z" joint="Neck_z" gear="500" />
    <motor name="Head_x" joint="Head_x" gear="500" />
    <motor name="Head_y" joint="Head_y" gear="500" />
    <motor name="Head_z" joint="Head_z" gear="500" />
    <motor name="L_Thorax_x" joint="L_Thorax_x" gear="500" />
    <motor name="L_Thorax_y" joint="L_Thorax_y" gear="500" />
    <motor name="L_Thorax_z" joint="L_Thorax_z" gear="500" />
    <motor name="L_Shoulder_x" joint="L_Shoulder_x" gear="500" />
    <motor name="L_Shoulder_y" joint="L_Shoulder_y" gear="500" />
    <motor name="L_Shoulder_z" joint="L_Shoulder_z" gear="500" />
    <motor name="L_Elbow_x" joint="L_Elbow_x" gear="500" />
    <motor name="L_Elbow_y" joint="L_Elbow_y" gear="500" />
    <motor name="L_Elbow_z" joint="L_Elbow_z" gear="500" />
    <motor name="L_Wrist_x" joint="L_Wrist_x" gear="500" />
    <motor name="L_Wrist_y" joint="L_Wrist_y" gear="500" />
    <motor name="L_Wrist_z" joint="L_Wrist_z" gear="500" />
    <motor name="L_Hand_x" joint="L_Hand_x" gear="500" />
    <motor name="L_Hand_y" joint="L_Hand_y" gear="500" />
    <motor name="L_Hand_z" joint="L_Hand_z" gear="500" />
    <motor name="R_Thorax_x" joint="R_Thorax_x" gear="500" />
    <motor name="R_Thorax_y" joint="R_Thorax_y" gear="500" />
    <motor name="R_Thorax_z" joint="R_Thorax_z" gear="500" />
    <motor name="R_Shoulder_x" joint="R_Shoulder_x" gear="500" />
    <motor name="R_Shoulder_y" joint="R_Shoulder_y" gear="500" />
    <motor name="R_Shoulder_z" joint="R_Shoulder_z" gear="500" />
    <motor name="R_Elbow_x" joint="R_Elbow_x" gear="500" />
    <motor name="R_Elbow_y" joint="R_Elbow_y" gear="500" />
    <motor name="R_Elbow_z" joint="R_Elbow_z" gear="500" />
    <motor name="R_Wrist_x" joint="R_Wrist_x" gear="500" />
    <motor name="R_Wrist_y" joint="R_Wrist_y" gear="500" />
    <motor name="R_Wrist_z" joint="R_Wrist_z" gear="500" />
    <motor name="R_Hand_x" joint="R_Hand_x" gear="500" />
    <motor name="R_Hand_y" joint="R_Hand_y" gear="500" />
    <motor name="R_Hand_z" joint="R_Hand_z" gear="500" />
  </actuator>
  <contact>
    <exclude body1="Torso" body2="Chest" />
    <exclude body1="Head" body2="Chest" />
    <exclude body1="R_Knee" body2="R_Toe" />
    <exclude body1="R_Knee" body2="L_Ankle" />
    <exclude body1="R_Knee" body2="L_Toe" />
    <exclude body1="L_Knee" body2="L_Toe" />
    <exclude body1="L_Knee" body2="R_Ankle" />
    <exclude body1="L_Knee" body2="R_Toe" />
    <exclude body1="L_Shoulder" body2="Chest" />
    <exclude body1="R_Shoulder" body2="Chest" />
  </contact>
  <sensor />
  <size njmax="700" nconmax="700" />
</mujoco>