<mujoco model="humanoid">
  <compiler coordinate="local" />
  <default>
    <joint damping="0.0" armature="0.01" stiffness="0.0" limited="true" />
    <geom conaffinity="1" condim="3" contype="7" margin="0.001" rgba="0.8 0.6 .4 1" />
  </default>
  <asset>
    <texture type="skybox" builtin="gradient" rgb1=".4 .5 .6" rgb2="0 0 0" width="100" height="100" />
    <texture builtin="flat" height="1278" mark="cross" markrgb="1 1 1" name="texgeom" random="0.01" rgb1="0.8 0.6 0.4" rgb2="0.8 0.6 0.4" type="cube" width="127" />
    <texture builtin="checker" height="100" name="texplane" rgb1="0 0 0" rgb2="0.8 0.8 0.8" type="2d" width="100" />
    <material name="MatPlane" reflectance="0.5" shininess="1" specular="1" texrepeat="60 60" texture="texplane" />
    <material name="geom" texture="texgeom" texuniform="true" />
  </asset>
  <worldbody>
    <light cutoff="100" diffuse="1 1 1" dir="-0 0 -1.3" directional="true" exponent="1" pos="0 0 1.3" specular=".1 .1 .1" />
    <geom conaffinity="1" condim="3" name="floor" pos="0 0 0" rgba="0.8 0.9 0.8 1" size="100 100 .2" type="plane" material="MatPlane" />
    <body name="Pelvis" pos="-0.003 -0.2238 0.0222">
      <freejoint name="Pelvis" />
      <geom type="box" pos="-0.0132 -0.0006 -0.0084" size="0.075 0.1025 0.0722" quat="1.0000 0.0000 0.0000 0.0000" density="1000" />
      <body name="L_Hip" pos="-0.0084 0.0646 -0.09">
        <joint name="L_Hip_x" type="hinge" pos="0 0 0" axis="1 0 0" stiffness="800" damping="80" armature="0.02" range="-180.0000 180.0000" />
        <joint name="L_Hip_y" type="hinge" pos="0 0 0" axis="0 1 0" stiffness="800" damping="80" armature="0.02" range="-180.0000 180.0000" />
        <joint name="L_Hip_z" type="hinge" pos="0 0 0" axis="0 0 1" stiffness="800" damping="80" armature="0.02" range="-180.0000 180.0000" />
        <geom type="capsule" contype="1" conaffinity="1" density="2040.816327" fromto="0.0004 0.0085 -0.0800 0.0018 0.0340 -0.3202" size="0.0602" />
        <body name="L_Knee" pos="0.0022 0.0425 -0.4002">
          <joint name="L_Knee_x" type="hinge" pos="0 0 0" axis="1 0 0" stiffness="800" damping="80" armature="0.02" range="-180.0000 180.0000" />
          <joint name="L_Knee_y" type="hinge" pos="0 0 0" axis="0 1 0" stiffness="800" damping="80" armature="0.02" range="-180.0000 180.0000" />
          <joint name="L_Knee_z" type="hinge" pos="0 0 0" axis="0 0 1" stiffness="800" damping="80" armature="0.02" range="-180.0000 180.0000" />
          <geom type="capsule" contype="1" conaffinity="1" density="1234.567901" fromto="-0.0085 -0.0030 -0.0847 -0.0338 -0.0121 -0.3386" size="0.0538" />
          <body name="L_Ankle" pos="-0.0423 -0.0151 -0.4233">
            <joint name="L_Ankle_x" type="hinge" pos="0 0 0" axis="1 0 0" stiffness="800" damping="80" armature="0.02" range="-180.0000 180.0000" />
            <joint name="L_Ankle_y" type="hinge" pos="0 0 0" axis="0 1 0" stiffness="800" damping="80" armature="0.02" range="-180.0000 180.0000" />
            <joint name="L_Ankle_z" type="hinge" pos="0 0 0" axis="0 0 1" stiffness="800" damping="80" armature="0.02" range="-180.0000 180.0000" />
            <geom type="box" pos="0.0257 0.0264 -0.0248" size="0.0878 0.0506 0.0474" quat="1.0000 0.0000 0.0000 0.0000" density="1000" />
            <body name="L_Toe" pos="0.1242 0.0301 -0.0581">
              <joint name="L_Toe_x" type="hinge" pos="0 0 0" axis="1 0 0" stiffness="500" damping="50" armature="0.02" range="-180.0000 180.0000" />
              <joint name="L_Toe_y" type="hinge" pos="0 0 0" axis="0 1 0" stiffness="500" damping="50" armature="0.02" range="-180.0000 180.0000" />
              <joint name="L_Toe_z" type="hinge" pos="0 0 0" axis="0 0 1" stiffness="500" damping="50" armature="0.02" range="-180.0000 180.0000" />
              <geom type="box" pos="0.0259 -0.0037 0.0067" size="0.0506 0.0487 0.0208" quat="1.0000 0.0000 0.0000 0.0000" density="1000" />
            </body>
          </body>
        </body>
      </body>
      <body name="R_Hip" pos="-0.0072 -0.0632 -0.0886">
        <joint name="R_Hip_x" type="hinge" pos="0 0 0" axis="1 0 0" stiffness="800" damping="80" armature="0.02" range="-180.0000 180.0000" />
        <joint name="R_Hip_y" type="hinge" pos="0 0 0" axis="0 1 0" stiffness="800" damping="80" armature="0.02" range="-180.0000 180.0000" />
        <joint name="R_Hip_z" type="hinge" pos="0 0 0" axis="0 0 1" stiffness="800" damping="80" armature="0.02" range="-180.0000 180.0000" />
        <geom type="capsule" contype="1" conaffinity="1" density="2040.816327" fromto="-0.0009 -0.0090 -0.0815 -0.0034 -0.0359 -0.3259" size="0.0589" />
        <body name="R_Knee" pos="-0.0043 -0.0449 -0.4074">
          <joint name="R_Knee_x" type="hinge" pos="0 0 0" axis="1 0 0" stiffness="800" damping="80" armature="0.02" range="-180.0000 180.0000" />
          <joint name="R_Knee_y" type="hinge" pos="0 0 0" axis="0 1 0" stiffness="800" damping="80" armature="0.02" range="-180.0000 180.0000" />
          <joint name="R_Knee_z" type="hinge" pos="0 0 0" axis="0 0 1" stiffness="800" damping="80" armature="0.02" range="-180.0000 180.0000" />
          <geom type="capsule" contype="1" conaffinity="1" density="1234.567901" fromto="-0.0081 0.0035 -0.0846 -0.0326 0.0139 -0.3385" size="0.0538" />
          <body name="R_Ankle" pos="-0.0407 0.0174 -0.4231">
            <joint name="R_Ankle_x" type="hinge" pos="0 0 0" axis="1 0 0" stiffness="800" damping="80" armature="0.02" range="-180.0000 180.0000" />
            <joint name="R_Ankle_y" type="hinge" pos="0 0 0" axis="0 1 0" stiffness="800" damping="80" armature="0.02" range="-180.0000 180.0000" />
            <joint name="R_Ankle_z" type="hinge" pos="0 0 0" axis="0 0 1" stiffness="800" damping="80" armature="0.02" range="-180.0000 180.0000" />
            <geom type="box" pos="0.0273 -0.0233 -0.0184" size="0.09 0.0493 0.0492" quat="1.0000 0.0000 0.0000 0.0000" density="1000" />
            <body name="R_Toe" pos="0.1286 -0.0272 -0.0511">
              <joint name="R_Toe_x" type="hinge" pos="0 0 0" axis="1 0 0" stiffness="500" damping="50" armature="0.02" range="-180.0000 180.0000" />
              <joint name="R_Toe_y" type="hinge" pos="0 0 0" axis="0 1 0" stiffness="500" damping="50" armature="0.02" range="-180.0000 180.0000" />
              <joint name="R_Toe_z" type="hinge" pos="0 0 0" axis="0 0 1" stiffness="500" damping="50" armature="0.02" range="-180.0000 180.0000" />
              <geom type="box" pos="0.0249 0.0039 0.0051" size="0.0516 0.0485 0.0216" quat="1.0000 0.0000 0.0000 0.0000" density="1000" />
            </body>
          </body>
        </body>
      </body>
      <body name="Torso" pos="-0.0258 -0.0028 0.1101">
        <joint name="Torso_x" type="hinge" pos="0 0 0" axis="1 0 0" stiffness="1000" damping="100" armature="0.02" range="-180.0000 180.0000" />
        <joint name="Torso_y" type="hinge" pos="0 0 0" axis="0 1 0" stiffness="1000" damping="100" armature="0.02" range="-180.0000 180.0000" />
        <joint name="Torso_z" type="hinge" pos="0 0 0" axis="0 0 1" stiffness="1000" damping="100" armature="0.02" range="-180.0000 180.0000" />
        <geom type="capsule" contype="1" conaffinity="1" density="2040.816327" fromto="0.0023 0.0032 0.0639 0.0029 0.0039 0.0780" size="0.0736" />
        <body name="Spine" pos="0.0052 0.0072 0.1419">
          <joint name="Spine_x" type="hinge" pos="0 0 0" axis="1 0 0" stiffness="1000" damping="100" armature="0.02" range="-180.0000 180.0000" />
          <joint name="Spine_y" type="hinge" pos="0 0 0" axis="0 1 0" stiffness="1000" damping="100" armature="0.02" range="-180.0000 180.0000" />
          <joint name="Spine_z" type="hinge" pos="0 0 0" axis="0 0 1" stiffness="1000" damping="100" armature="0.02" range="-180.0000 180.0000" />
          <geom type="capsule" contype="1" conaffinity="1" density="2040.816327" fromto="0.0087 0.0005 0.0247 0.0106 0.0006 0.0301" size="0.0716" />
          <body name="Chest" pos="0.0193 0.0011 0.0548">
            <joint name="Chest_x" type="hinge" pos="0 0 0" axis="1 0 0" stiffness="1000" damping="100" armature="0.02" range="-180.0000 180.0000" />
            <joint name="Chest_y" type="hinge" pos="0 0 0" axis="0 1 0" stiffness="1000" damping="100" armature="0.02" range="-180.0000 180.0000" />
            <joint name="Chest_z" type="hinge" pos="0 0 0" axis="0 0 1" stiffness="1000" damping="100" armature="0.02" range="-180.0000 180.0000" />
            <geom type="capsule" contype="1" conaffinity="1" density="2040.816327" fromto="-0.0131 -0.0013 0.0678 -0.0160 -0.0016 0.0829" size="0.0967" />
            <body name="Neck" pos="-0.0288 -0.0045 0.2139">
              <joint name="Neck_x" type="hinge" pos="0 0 0" axis="1 0 0" stiffness="500" damping="50" armature="0.02" range="-180.0000 180.0000" />
              <joint name="Neck_y" type="hinge" pos="0 0 0" axis="0 1 0" stiffness="500" damping="50" armature="0.02" range="-180.0000 180.0000" />
              <joint name="Neck_z" type="hinge" pos="0 0 0" axis="0 0 1" stiffness="500" damping="50" armature="0.02" range="-180.0000 180.0000" />
              <geom type="capsule" contype="1" conaffinity="1" density="1000" fromto="0.0104 0.0015 0.0139 0.0418 0.0061 0.0558" size="0.0443" />
              <body name="Head" pos="0.0522 0.0076 0.0697">
                <joint name="Head_x" type="hinge" pos="0 0 0" axis="1 0 0" stiffness="500" damping="50" armature="0.02" range="-180.0000 180.0000" />
                <joint name="Head_y" type="hinge" pos="0 0 0" axis="0 1 0" stiffness="500" damping="50" armature="0.02" range="-180.0000 180.0000" />
                <joint name="Head_z" type="hinge" pos="0 0 0" axis="0 0 1" stiffness="500" damping="50" armature="0.02" range="-180.0000 180.0000" />
                <geom type="box" pos="-0.0109 -0.0039 0.0875" size="0.0764 0.0608 0.1147" quat="1.0000 0.0000 0.0000 0.0000" density="1000" />
                
              </body>
            </body>
            <body name="L_Thorax" pos="-0.0271 0.0793 0.1211">
              <joint name="L_Thorax_x" type="hinge" pos="0 0 0" axis="1 0 0" stiffness="500" damping="50" armature="0.02" range="-180.0000 180.0000" />
              <joint name="L_Thorax_y" type="hinge" pos="0 0 0" axis="0 1 0" stiffness="500" damping="50" armature="0.02" range="-180.0000 180.0000" />
              <joint name="L_Thorax_z" type="hinge" pos="0 0 0" axis="0 0 1" stiffness="500" damping="50" armature="0.02" range="-180.0000 180.0000" />
              <geom type="capsule" contype="1" conaffinity="1" density="1000" fromto="-0.0017 0.0189 0.0063 -0.0069 0.0757 0.0253" size="0.0524" />
              <body name="L_Shoulder" pos="-0.0086 0.0946 0.0317">
                <joint name="L_Shoulder_x" type="hinge" pos="0 0 0" axis="1 0 0" stiffness="500" damping="50" armature="0.02" range="-720.0000 720.0000" />
                <joint name="L_Shoulder_y" type="hinge" pos="0 0 0" axis="0 1 0" stiffness="500" damping="50" armature="0.02" range="-720.0000 720.0000" />
                <joint name="L_Shoulder_z" type="hinge" pos="0 0 0" axis="0 0 1" stiffness="500" damping="50" armature="0.02" range="-720.0000 720.0000" />
                <geom type="capsule" contype="1" conaffinity="1" density="1000" fromto="-0.0054 0.0546 -0.0035 -0.0215 0.2183 -0.0140" size="0.0511" />
                <body name="L_Elbow" pos="-0.0269 0.2729 -0.0175">
                  <joint name="L_Elbow_x" type="hinge" pos="0 0 0" axis="1 0 0" stiffness="500" damping="50" armature="0.02" range="-720.0000 720.0000" />
                  <joint name="L_Elbow_y" type="hinge" pos="0 0 0" axis="0 1 0" stiffness="500" damping="50" armature="0.02" range="-720.0000 720.0000" />
                  <joint name="L_Elbow_z" type="hinge" pos="0 0 0" axis="0 0 1" stiffness="500" damping="50" armature="0.02" range="-720.0000 720.0000" />
                  <geom type="capsule" contype="1" conaffinity="1" density="1000" fromto="-0.0005 0.0531 0.0020 -0.0022 0.2124 0.0078" size="0.0404" />
                  <body name="L_Wrist" pos="-0.0027 0.2655 0.0098">
                    <joint name="L_Wrist_x" type="hinge" pos="0 0 0" axis="1 0 0" stiffness="300" damping="30" armature="0.02" range="-180.0000 180.0000" />
                    <joint name="L_Wrist_y" type="hinge" pos="0 0 0" axis="0 1 0" stiffness="300" damping="30" armature="0.02" range="-180.0000 180.0000" />
                    <joint name="L_Wrist_z" type="hinge" pos="0 0 0" axis="0 0 1" stiffness="300" damping="30" armature="0.02" range="-180.0000 180.0000" />
                    <geom type="capsule" contype="1" conaffinity="1" density="1000" fromto="-0.0033 0.0175 -0.0014 -0.0132 0.0701 -0.0058" size="0.0328" />
                    <body name="L_Hand" pos="-0.0165 0.0876 -0.0072">
                      <joint name="L_Hand_x" type="hinge" pos="0 0 0" axis="1 0 0" stiffness="300" damping="30" armature="0.02" range="-180.0000 180.0000" />
                      <joint name="L_Hand_y" type="hinge" pos="0 0 0" axis="0 1 0" stiffness="300" damping="30" armature="0.02" range="-180.0000 180.0000" />
                      <joint name="L_Hand_z" type="hinge" pos="0 0 0" axis="0 0 1" stiffness="300" damping="30" armature="0.02" range="-180.0000 180.0000" />
                      <geom type="box" pos="-0.0052 0.0509 0.0011" size="0.0556 0.0601 0.0162" quat="1.0000 0.0000 0.0000 0.0000" density="1000" />
                    </body>
                  </body>
                </body>
              </body>
            </body>
            <body name="R_Thorax" pos="-0.0314 -0.0834 0.1173">
              <joint name="R_Thorax_x" type="hinge" pos="0 0 0" axis="1 0 0" stiffness="500" damping="50" armature="0.02" range="-180.0000 180.0000" />
              <joint name="R_Thorax_y" type="hinge" pos="0 0 0" axis="0 1 0" stiffness="500" damping="50" armature="0.02" range="-180.0000 180.0000" />
              <joint name="R_Thorax_z" type="hinge" pos="0 0 0" axis="0 0 1" stiffness="500" damping="50" armature="0.02" range="-180.0000 180.0000" />
              <geom type="capsule" contype="1" conaffinity="1" density="1000" fromto="-0.0015 -0.0200 0.0069 -0.0059 -0.0801 0.0278" size="0.0513" />
              <body name="R_Shoulder" pos="-0.0074 -0.1001 0.0347">
                <joint name="R_Shoulder_x" type="hinge" pos="0 0 0" axis="1 0 0" stiffness="500" damping="50" armature="0.02" range="-720.0000 720.0000" />
                <joint name="R_Shoulder_y" type="hinge" pos="0 0 0" axis="0 1 0" stiffness="500" damping="50" armature="0.02" range="-720.0000 720.0000" />
                <joint name="R_Shoulder_z" type="hinge" pos="0 0 0" axis="0 0 1" stiffness="500" damping="50" armature="0.02" range="-720.0000 720.0000" />
                <geom type="capsule" contype="1" conaffinity="1" density="1000" fromto="-0.0043 -0.0530 -0.0033 -0.0172 -0.2121 -0.0134" size="0.0524" />
                <body name="R_Elbow" pos="-0.0215 -0.2651 -0.0167">
                  <joint name="R_Elbow_x" type="hinge" pos="0 0 0" axis="1 0 0" stiffness="500" damping="50" armature="0.02" range="-720.0000 720.0000" />
                  <joint name="R_Elbow_y" type="hinge" pos="0 0 0" axis="0 1 0" stiffness="500" damping="50" armature="0.02" range="-720.0000 720.0000" />
                  <joint name="R_Elbow_z" type="hinge" pos="0 0 0" axis="0 0 1" stiffness="500" damping="50" armature="0.02" range="-720.0000 720.0000" />
                  <geom type="capsule" contype="1" conaffinity="1" density="1000" fromto="-0.0016 -0.0540 0.0013 -0.0064 -0.2159 0.0052" size="0.0407" />
                  <body name="R_Wrist" pos="-0.008 -0.2699 0.0066">
                    <joint name="R_Wrist_x" type="hinge" pos="0 0 0" axis="1 0 0" stiffness="300" damping="30" armature="0.02" range="-180.0000 180.0000" />
                    <joint name="R_Wrist_y" type="hinge" pos="0 0 0" axis="0 1 0" stiffness="300" damping="30" armature="0.02" range="-180.0000 180.0000" />
                    <joint name="R_Wrist_z" type="hinge" pos="0 0 0" axis="0 0 1" stiffness="300" damping="30" armature="0.02" range="-180.0000 180.0000" />
                    <geom type="capsule" contype="1" conaffinity="1" density="1000" fromto="-0.0020 -0.0175 -0.0010 -0.0081 -0.0699 -0.0042" size="0.0333" />
                    <body name="R_Hand" pos="-0.0101 -0.0873 -0.0052">
                      <joint name="R_Hand_x" type="hinge" pos="0 0 0" axis="1 0 0" stiffness="300" damping="30" armature="0.02" range="-180.0000 180.0000" />
                      <joint name="R_Hand_y" type="hinge" pos="0 0 0" axis="0 1 0" stiffness="300" damping="30" armature="0.02" range="-180.0000 180.0000" />
                      <joint name="R_Hand_z" type="hinge" pos="0 0 0" axis="0 0 1" stiffness="300" damping="30" armature="0.02" range="-180.0000 180.0000" />
                      <geom type="box" pos="-0.0078 -0.0472 -0.0008" size="0.056 0.058 0.0167" quat="1.0000 0.0000 0.0000 0.0000" density="1000" />
                    </body>
                  </body>
                </body>
              </body>
            </body>
          </body>
        </body>
      </body>
    </body>
  </worldbody>
  <actuator>
    <motor name="L_Hip_x" joint="L_Hip_x" gear="500" />
    <motor name="L_Hip_y" joint="L_Hip_y" gear="500" />
    <motor name="L_Hip_z" joint="L_Hip_z" gear="500" />
    <motor name="L_Knee_x" joint="L_Knee_x" gear="500" />
    <motor name="L_Knee_y" joint="L_Knee_y" gear="500" />
    <motor name="L_Knee_z" joint="L_Knee_z" gear="500" />
    <motor name="L_Ankle_x" joint="L_Ankle_x" gear="500" />
    <motor name="L_Ankle_y" joint="L_Ankle_y" gear="500" />
    <motor name="L_Ankle_z" joint="L_Ankle_z" gear="500" />
    <motor name="L_Toe_x" joint="L_Toe_x" gear="500" />
    <motor name="L_Toe_y" joint="L_Toe_y" gear="500" />
    <motor name="L_Toe_z" joint="L_Toe_z" gear="500" />
    <motor name="R_Hip_x" joint="R_Hip_x" gear="500" />
    <motor name="R_Hip_y" joint="R_Hip_y" gear="500" />
    <motor name="R_Hip_z" joint="R_Hip_z" gear="500" />
    <motor name="R_Knee_x" joint="R_Knee_x" gear="500" />
    <motor name="R_Knee_y" joint="R_Knee_y" gear="500" />
    <motor name="R_Knee_z" joint="R_Knee_z" gear="500" />
    <motor name="R_Ankle_x" joint="R_Ankle_x" gear="500" />
    <motor name="R_Ankle_y" joint="R_Ankle_y" gear="500" />
    <motor name="R_Ankle_z" joint="R_Ankle_z" gear="500" />
    <motor name="R_Toe_x" joint="R_Toe_x" gear="500" />
    <motor name="R_Toe_y" joint="R_Toe_y" gear="500" />
    <motor name="R_Toe_z" joint="R_Toe_z" gear="500" />
    <motor name="Torso_x" joint="Torso_x" gear="500" />
    <motor name="Torso_y" joint="Torso_y" gear="500" />
    <motor name="Torso_z" joint="Torso_z" gear="500" />
    <motor name="Spine_x" joint="Spine_x" gear="500" />
    <motor name="Spine_y" joint="Spine_y" gear="500" />
    <motor name="Spine_z" joint="Spine_z" gear="500" />
    <motor name="Chest_x" joint="Chest_x" gear="500" />
    <motor name="Chest_y" joint="Chest_y" gear="500" />
    <motor name="Chest_z" joint="Chest_z" gear="500" />
    <motor name="Neck_x" joint="Neck_x" gear="500" />
    <motor name="Neck_y" joint="Neck_y" gear="500" />
    <motor name="Neck_z" joint="Neck_z" gear="500" />
    <motor name="Head_x" joint="Head_x" gear="500" />
    <motor name="Head_y" joint="Head_y" gear="500" />
    <motor name="Head_z" joint="Head_z" gear="500" />
    <motor name="L_Thorax_x" joint="L_Thorax_x" gear="500" />
    <motor name="L_Thorax_y" joint="L_Thorax_y" gear="500" />
    <motor name="L_Thorax_z" joint="L_Thorax_z" gear="500" />
    <motor name="L_Shoulder_x" joint="L_Shoulder_x" gear="500" />
    <motor name="L_Shoulder_y" joint="L_Shoulder_y" gear="500" />
    <motor name="L_Shoulder_z" joint="L_Shoulder_z" gear="500" />
    <motor name="L_Elbow_x" joint="L_Elbow_x" gear="500" />
    <motor name="L_Elbow_y" joint="L_Elbow_y" gear="500" />
    <motor name="L_Elbow_z" joint="L_Elbow_z" gear="500" />
    <motor name="L_Wrist_x" joint="L_Wrist_x" gear="500" />
    <motor name="L_Wrist_y" joint="L_Wrist_y" gear="500" />
    <motor name="L_Wrist_z" joint="L_Wrist_z" gear="500" />
    <motor name="L_Hand_x" joint="L_Hand_x" gear="500" />
    <motor name="L_Hand_y" joint="L_Hand_y" gear="500" />
    <motor name="L_Hand_z" joint="L_Hand_z" gear="500" />
    <motor name="R_Thorax_x" joint="R_Thorax_x" gear="500" />
    <motor name="R_Thorax_y" joint="R_Thorax_y" gear="500" />
    <motor name="R_Thorax_z" joint="R_Thorax_z" gear="500" />
    <motor name="R_Shoulder_x" joint="R_Shoulder_x" gear="500" />
    <motor name="R_Shoulder_y" joint="R_Shoulder_y" gear="500" />
    <motor name="R_Shoulder_z" joint="R_Shoulder_z" gear="500" />
    <motor name="R_Elbow_x" joint="R_Elbow_x" gear="500" />
    <motor name="R_Elbow_y" joint="R_Elbow_y" gear="500" />
    <motor name="R_Elbow_z" joint="R_Elbow_z" gear="500" />
    <motor name="R_Wrist_x" joint="R_Wrist_x" gear="500" />
    <motor name="R_Wrist_y" joint="R_Wrist_y" gear="500" />
    <motor name="R_Wrist_z" joint="R_Wrist_z" gear="500" />
    <motor name="R_Hand_x" joint="R_Hand_x" gear="500" />
    <motor name="R_Hand_y" joint="R_Hand_y" gear="500" />
    <motor name="R_Hand_z" joint="R_Hand_z" gear="500" />
  </actuator>
  <contact>
    <exclude body1="Torso" body2="Chest" />
    <exclude body1="Head" body2="Chest" />
    <exclude body1="R_Knee" body2="R_Toe" />
    <exclude body1="R_Knee" body2="L_Ankle" />
    <exclude body1="R_Knee" body2="L_Toe" />
    <exclude body1="L_Knee" body2="L_Toe" />
    <exclude body1="L_Knee" body2="R_Ankle" />
    <exclude body1="L_Knee" body2="R_Toe" />
    <exclude body1="L_Shoulder" body2="Chest" />
    <exclude body1="R_Shoulder" body2="Chest" />
  </contact>
  <sensor />
  <size njmax="700" nconmax="700" />
</mujoco>