<mujoco model="humanoid">
  <compiler coordinate="local" />
  <default>
    <joint damping="0.0" armature="0.01" stiffness="0.0" limited="true" />
    <geom conaffinity="1" condim="3" contype="7" margin="0.001" rgba="0.8 0.6 .4 1" />
  </default>
  <asset>
    <texture type="skybox" builtin="gradient" rgb1=".4 .5 .6" rgb2="0 0 0" width="100" height="100" />
    <texture builtin="flat" height="1278" mark="cross" markrgb="1 1 1" name="texgeom" random="0.01" rgb1="0.8 0.6 0.4" rgb2="0.8 0.6 0.4" type="cube" width="127" />
    <texture builtin="checker" height="100" name="texplane" rgb1="0 0 0" rgb2="0.8 0.8 0.8" type="2d" width="100" />
    <material name="MatPlane" reflectance="0.5" shininess="1" specular="1" texrepeat="60 60" texture="texplane" />
    <material name="geom" texture="texgeom" texuniform="true" />
  </asset>
  <worldbody>
    <light cutoff="100" diffuse="1 1 1" dir="-0 0 -1.3" directional="true" exponent="1" pos="0 0 1.3" specular=".1 .1 .1" />
    <geom conaffinity="1" condim="3" name="floor" pos="0 0 0" rgba="0.8 0.9 0.8 1" size="100 100 .2" type="plane" material="MatPlane" />
    <body name="Pelvis" pos="-0.002 -0.2278 0.0285">
      <freejoint name="Pelvis" />
      <geom type="box" pos="-0.0078 0.0000 -0.0122" size="0.084 0.1097 0.0739" quat="1.0000 0.0000 0.0000 0.0000" density="1000" />
      <body name="L_Hip" pos="-0.0071 0.0709 -0.0931">
        <joint name="L_Hip_x" type="hinge" pos="0 0 0" axis="1 0 0" stiffness="800" damping="80" armature="0.02" range="-180.0000 180.0000" />
        <joint name="L_Hip_y" type="hinge" pos="0 0 0" axis="0 1 0" stiffness="800" damping="80" armature="0.02" range="-180.0000 180.0000" />
        <joint name="L_Hip_z" type="hinge" pos="0 0 0" axis="0 0 1" stiffness="800" damping="80" armature="0.02" range="-180.0000 180.0000" />
        <geom type="capsule" contype="1" conaffinity="1" density="2040.816327" fromto="-0.0008 0.0072 -0.0772 -0.0031 0.0288 -0.3088" size="0.0633" />
        <body name="L_Knee" pos="-0.0039 0.036 -0.386">
          <joint name="L_Knee_x" type="hinge" pos="0 0 0" axis="1 0 0" stiffness="800" damping="80" armature="0.02" range="-180.0000 180.0000" />
          <joint name="L_Knee_y" type="hinge" pos="0 0 0" axis="0 1 0" stiffness="800" damping="80" armature="0.02" range="-180.0000 180.0000" />
          <joint name="L_Knee_z" type="hinge" pos="0 0 0" axis="0 0 1" stiffness="800" damping="80" armature="0.02" range="-180.0000 180.0000" />
          <geom type="capsule" contype="1" conaffinity="1" density="1234.567901" fromto="-0.0090 -0.0028 -0.0820 -0.0361 -0.0113 -0.3281" size="0.0556" />
          <body name="L_Ankle" pos="-0.0452 -0.0141 -0.4101">
            <joint name="L_Ankle_x" type="hinge" pos="0 0 0" axis="1 0 0" stiffness="800" damping="80" armature="0.02" range="-180.0000 180.0000" />
            <joint name="L_Ankle_y" type="hinge" pos="0 0 0" axis="0 1 0" stiffness="800" damping="80" armature="0.02" range="-180.0000 180.0000" />
            <joint name="L_Ankle_z" type="hinge" pos="0 0 0" axis="0 0 1" stiffness="800" damping="80" armature="0.02" range="-180.0000 180.0000" />
            <geom type="box" pos="0.0248 0.0239 -0.0245" size="0.0868 0.0493 0.0473" quat="1.0000 0.0000 0.0000 0.0000" density="1000" />
            <body name="L_Toe" pos="0.1219 0.0271 -0.0572">
              <joint name="L_Toe_x" type="hinge" pos="0 0 0" axis="1 0 0" stiffness="500" damping="50" armature="0.02" range="-180.0000 180.0000" />
              <joint name="L_Toe_y" type="hinge" pos="0 0 0" axis="0 1 0" stiffness="500" damping="50" armature="0.02" range="-180.0000 180.0000" />
              <joint name="L_Toe_z" type="hinge" pos="0 0 0" axis="0 0 1" stiffness="500" damping="50" armature="0.02" range="-180.0000 180.0000" />
              <geom type="box" pos="0.0254 -0.0031 0.0058" size="0.0507 0.0486 0.0204" quat="1.0000 0.0000 0.0000 0.0000" density="1000" />
            </body>
          </body>
        </body>
      </body>
      <body name="R_Hip" pos="-0.0048 -0.069 -0.0921">
        <joint name="R_Hip_x" type="hinge" pos="0 0 0" axis="1 0 0" stiffness="800" damping="80" armature="0.02" range="-180.0000 180.0000" />
        <joint name="R_Hip_y" type="hinge" pos="0 0 0" axis="0 1 0" stiffness="800" damping="80" armature="0.02" range="-180.0000 180.0000" />
        <joint name="R_Hip_z" type="hinge" pos="0 0 0" axis="0 0 1" stiffness="800" damping="80" armature="0.02" range="-180.0000 180.0000" />
        <geom type="capsule" contype="1" conaffinity="1" density="2040.816327" fromto="-0.0017 -0.0080 -0.0788 -0.0069 -0.0321 -0.3152" size="0.0623" />
        <body name="R_Knee" pos="-0.0087 -0.0401 -0.3939">
          <joint name="R_Knee_x" type="hinge" pos="0 0 0" axis="1 0 0" stiffness="800" damping="80" armature="0.02" range="-180.0000 180.0000" />
          <joint name="R_Knee_y" type="hinge" pos="0 0 0" axis="0 1 0" stiffness="800" damping="80" armature="0.02" range="-180.0000 180.0000" />
          <joint name="R_Knee_z" type="hinge" pos="0 0 0" axis="0 0 1" stiffness="800" damping="80" armature="0.02" range="-180.0000 180.0000" />
          <geom type="capsule" contype="1" conaffinity="1" density="1234.567901" fromto="-0.0088 0.0033 -0.0821 -0.0350 0.0130 -0.3285" size="0.0555" />
          <body name="R_Ankle" pos="-0.0438 0.0163 -0.4106">
            <joint name="R_Ankle_x" type="hinge" pos="0 0 0" axis="1 0 0" stiffness="800" damping="80" armature="0.02" range="-180.0000 180.0000" />
            <joint name="R_Ankle_y" type="hinge" pos="0 0 0" axis="0 1 0" stiffness="800" damping="80" armature="0.02" range="-180.0000 180.0000" />
            <joint name="R_Ankle_z" type="hinge" pos="0 0 0" axis="0 0 1" stiffness="800" damping="80" armature="0.02" range="-180.0000 180.0000" />
            <geom type="box" pos="0.0262 -0.0226 -0.0178" size="0.0882 0.049 0.0488" quat="1.0000 0.0000 0.0000 0.0000" density="1000" />
            <body name="R_Toe" pos="0.126 -0.0269 -0.0495">
              <joint name="R_Toe_x" type="hinge" pos="0 0 0" axis="1 0 0" stiffness="500" damping="50" armature="0.02" range="-180.0000 180.0000" />
              <joint name="R_Toe_y" type="hinge" pos="0 0 0" axis="0 1 0" stiffness="500" damping="50" armature="0.02" range="-180.0000 180.0000" />
              <joint name="R_Toe_z" type="hinge" pos="0 0 0" axis="0 0 1" stiffness="500" damping="50" armature="0.02" range="-180.0000 180.0000" />
              <geom type="box" pos="0.0230 0.0042 0.0049" size="0.0502 0.0485 0.022" quat="1.0000 0.0000 0.0000 0.0000" density="1000" />
            </body>
          </body>
        </body>
      </body>
      <body name="Torso" pos="-0.0278 -0.0026 0.1116">
        <joint name="Torso_x" type="hinge" pos="0 0 0" axis="1 0 0" stiffness="1000" damping="100" armature="0.02" range="-180.0000 180.0000" />
        <joint name="Torso_y" type="hinge" pos="0 0 0" axis="0 1 0" stiffness="1000" damping="100" armature="0.02" range="-180.0000 180.0000" />
        <joint name="Torso_z" type="hinge" pos="0 0 0" axis="0 0 1" stiffness="1000" damping="100" armature="0.02" range="-180.0000 180.0000" />
        <geom type="capsule" contype="1" conaffinity="1" density="2040.816327" fromto="0.0005 0.0026 0.0627 0.0006 0.0032 0.0767" size="0.0778" />
        <body name="Spine" pos="0.0011 0.0057 0.1394">
          <joint name="Spine_x" type="hinge" pos="0 0 0" axis="1 0 0" stiffness="1000" damping="100" armature="0.02" range="-180.0000 180.0000" />
          <joint name="Spine_y" type="hinge" pos="0 0 0" axis="0 1 0" stiffness="1000" damping="100" armature="0.02" range="-180.0000 180.0000" />
          <joint name="Spine_z" type="hinge" pos="0 0 0" axis="0 0 1" stiffness="1000" damping="100" armature="0.02" range="-180.0000 180.0000" />
          <geom type="capsule" contype="1" conaffinity="1" density="2040.816327" fromto="0.0115 0.0006 0.0244 0.0141 0.0008 0.0299" size="0.076" />
          <body name="Chest" pos="0.0256 0.0014 0.0543">
            <joint name="Chest_x" type="hinge" pos="0 0 0" axis="1 0 0" stiffness="1000" damping="100" armature="0.02" range="-180.0000 180.0000" />
            <joint name="Chest_y" type="hinge" pos="0 0 0" axis="0 1 0" stiffness="1000" damping="100" armature="0.02" range="-180.0000 180.0000" />
            <joint name="Chest_z" type="hinge" pos="0 0 0" axis="0 0 1" stiffness="1000" damping="100" armature="0.02" range="-180.0000 180.0000" />
            <geom type="capsule" contype="1" conaffinity="1" density="2040.816327" fromto="-0.0168 -0.0009 0.0693 -0.0205 -0.0011 0.0847" size="0.101" />
            <body name="Neck" pos="-0.0411 -0.0031 0.2178">
              <joint name="Neck_x" type="hinge" pos="0 0 0" axis="1 0 0" stiffness="500" damping="50" armature="0.02" range="-180.0000 180.0000" />
              <joint name="Neck_y" type="hinge" pos="0 0 0" axis="0 1 0" stiffness="500" damping="50" armature="0.02" range="-180.0000 180.0000" />
              <joint name="Neck_z" type="hinge" pos="0 0 0" axis="0 0 1" stiffness="500" damping="50" armature="0.02" range="-180.0000 180.0000" />
              <geom type="capsule" contype="1" conaffinity="1" density="1000" fromto="0.0105 0.0011 0.0133 0.0418 0.0044 0.0533" size="0.0441" />
              <body name="Head" pos="0.0523 0.0055 0.0667">
                <joint name="Head_x" type="hinge" pos="0 0 0" axis="1 0 0" stiffness="500" damping="50" armature="0.02" range="-180.0000 180.0000" />
                <joint name="Head_y" type="hinge" pos="0 0 0" axis="0 1 0" stiffness="500" damping="50" armature="0.02" range="-180.0000 180.0000" />
                <joint name="Head_z" type="hinge" pos="0 0 0" axis="0 0 1" stiffness="500" damping="50" armature="0.02" range="-180.0000 180.0000" />
                <geom type="box" pos="-0.0117 -0.0043 0.0885" size="0.0767 0.0612 0.1165" quat="1.0000 0.0000 0.0000 0.0000" density="1000" />
                
              </body>
            </body>
            <body name="L_Thorax" pos="-0.033 0.08 0.1236">
              <joint name="L_Thorax_x" type="hinge" pos="0 0 0" axis="1 0 0" stiffness="500" damping="50" armature="0.02" range="-180.0000 180.0000" />
              <joint name="L_Thorax_y" type="hinge" pos="0 0 0" axis="0 1 0" stiffness="500" damping="50" armature="0.02" range="-180.0000 180.0000" />
              <joint name="L_Thorax_z" type="hinge" pos="0 0 0" axis="0 0 1" stiffness="500" damping="50" armature="0.02" range="-180.0000 180.0000" />
              <geom type="capsule" contype="1" conaffinity="1" density="1000" fromto="-0.0018 0.0185 0.0063 -0.0073 0.0739 0.0252" size="0.0531" />
              <body name="L_Shoulder" pos="-0.0091 0.0924 0.0315">
                <joint name="L_Shoulder_x" type="hinge" pos="0 0 0" axis="1 0 0" stiffness="500" damping="50" armature="0.02" range="-720.0000 720.0000" />
                <joint name="L_Shoulder_y" type="hinge" pos="0 0 0" axis="0 1 0" stiffness="500" damping="50" armature="0.02" range="-720.0000 720.0000" />
                <joint name="L_Shoulder_z" type="hinge" pos="0 0 0" axis="0 0 1" stiffness="500" damping="50" armature="0.02" range="-720.0000 720.0000" />
                <geom type="capsule" contype="1" conaffinity="1" density="1000" fromto="-0.0057 0.0530 -0.0029 -0.0228 0.2121 -0.0116" size="0.0529" />
                <body name="L_Elbow" pos="-0.0285 0.2652 -0.0145">
                  <joint name="L_Elbow_x" type="hinge" pos="0 0 0" axis="1 0 0" stiffness="500" damping="50" armature="0.02" range="-720.0000 720.0000" />
                  <joint name="L_Elbow_y" type="hinge" pos="0 0 0" axis="0 1 0" stiffness="500" damping="50" armature="0.02" range="-720.0000 720.0000" />
                  <joint name="L_Elbow_z" type="hinge" pos="0 0 0" axis="0 0 1" stiffness="500" damping="50" armature="0.02" range="-720.0000 720.0000" />
                  <geom type="capsule" contype="1" conaffinity="1" density="1000" fromto="-0.0002 0.0512 0.0019 -0.0007 0.2046 0.0077" size="0.0413" />
                  <body name="L_Wrist" pos="-0.0009 0.2558 0.0096">
                    <joint name="L_Wrist_x" type="hinge" pos="0 0 0" axis="1 0 0" stiffness="300" damping="30" armature="0.02" range="-180.0000 180.0000" />
                    <joint name="L_Wrist_y" type="hinge" pos="0 0 0" axis="0 1 0" stiffness="300" damping="30" armature="0.02" range="-180.0000 180.0000" />
                    <joint name="L_Wrist_z" type="hinge" pos="0 0 0" axis="0 0 1" stiffness="300" damping="30" armature="0.02" range="-180.0000 180.0000" />
                    <geom type="capsule" contype="1" conaffinity="1" density="1000" fromto="-0.0031 0.0171 -0.0016 -0.0123 0.0685 -0.0066" size="0.0324" />
                    <body name="L_Hand" pos="-0.0153 0.0857 -0.0082">
                      <joint name="L_Hand_x" type="hinge" pos="0 0 0" axis="1 0 0" stiffness="300" damping="30" armature="0.02" range="-180.0000 180.0000" />
                      <joint name="L_Hand_y" type="hinge" pos="0 0 0" axis="0 1 0" stiffness="300" damping="30" armature="0.02" range="-180.0000 180.0000" />
                      <joint name="L_Hand_z" type="hinge" pos="0 0 0" axis="0 0 1" stiffness="300" damping="30" armature="0.02" range="-180.0000 180.0000" />
                      <geom type="box" pos="-0.0058 0.0502 0.0010" size="0.0548 0.0595 0.0161" quat="1.0000 0.0000 0.0000 0.0000" density="1000" />
                    </body>
                  </body>
                </body>
              </body>
            </body>
            <body name="R_Thorax" pos="-0.0378 -0.0829 0.1204">
              <joint name="R_Thorax_x" type="hinge" pos="0 0 0" axis="1 0 0" stiffness="500" damping="50" armature="0.02" range="-180.0000 180.0000" />
              <joint name="R_Thorax_y" type="hinge" pos="0 0 0" axis="0 1 0" stiffness="500" damping="50" armature="0.02" range="-180.0000 180.0000" />
              <joint name="R_Thorax_z" type="hinge" pos="0 0 0" axis="0 0 1" stiffness="500" damping="50" armature="0.02" range="-180.0000 180.0000" />
              <geom type="capsule" contype="1" conaffinity="1" density="1000" fromto="-0.0018 -0.0195 0.0067 -0.0072 -0.0780 0.0269" size="0.052" />
              <body name="R_Shoulder" pos="-0.0091 -0.0975 0.0336">
                <joint name="R_Shoulder_x" type="hinge" pos="0 0 0" axis="1 0 0" stiffness="500" damping="50" armature="0.02" range="-720.0000 720.0000" />
                <joint name="R_Shoulder_y" type="hinge" pos="0 0 0" axis="0 1 0" stiffness="500" damping="50" armature="0.02" range="-720.0000 720.0000" />
                <joint name="R_Shoulder_z" type="hinge" pos="0 0 0" axis="0 0 1" stiffness="500" damping="50" armature="0.02" range="-720.0000 720.0000" />
                <geom type="capsule" contype="1" conaffinity="1" density="1000" fromto="-0.0045 -0.0518 -0.0029 -0.0182 -0.2072 -0.0116" size="0.0542" />
                <body name="R_Elbow" pos="-0.0227 -0.259 -0.0144">
                  <joint name="R_Elbow_x" type="hinge" pos="0 0 0" axis="1 0 0" stiffness="500" damping="50" armature="0.02" range="-720.0000 720.0000" />
                  <joint name="R_Elbow_y" type="hinge" pos="0 0 0" axis="0 1 0" stiffness="500" damping="50" armature="0.02" range="-720.0000 720.0000" />
                  <joint name="R_Elbow_z" type="hinge" pos="0 0 0" axis="0 0 1" stiffness="500" damping="50" armature="0.02" range="-720.0000 720.0000" />
                  <geom type="capsule" contype="1" conaffinity="1" density="1000" fromto="-0.0011 -0.0522 0.0015 -0.0046 -0.2089 0.0061" size="0.0415" />
                  <body name="R_Wrist" pos="-0.0057 -0.2611 0.0076">
                    <joint name="R_Wrist_x" type="hinge" pos="0 0 0" axis="1 0 0" stiffness="300" damping="30" armature="0.02" range="-180.0000 180.0000" />
                    <joint name="R_Wrist_y" type="hinge" pos="0 0 0" axis="0 1 0" stiffness="300" damping="30" armature="0.02" range="-180.0000 180.0000" />
                    <joint name="R_Wrist_z" type="hinge" pos="0 0 0" axis="0 0 1" stiffness="300" damping="30" armature="0.02" range="-180.0000 180.0000" />
                    <geom type="capsule" contype="1" conaffinity="1" density="1000" fromto="-0.0021 -0.0172 -0.0012 -0.0083 -0.0687 -0.0049" size="0.033" />
                    <body name="R_Hand" pos="-0.0104 -0.0859 -0.0061">
                      <joint name="R_Hand_x" type="hinge" pos="0 0 0" axis="1 0 0" stiffness="300" damping="30" armature="0.02" range="-180.0000 180.0000" />
                      <joint name="R_Hand_y" type="hinge" pos="0 0 0" axis="0 1 0" stiffness="300" damping="30" armature="0.02" range="-180.0000 180.0000" />
                      <joint name="R_Hand_z" type="hinge" pos="0 0 0" axis="0 0 1" stiffness="300" damping="30" armature="0.02" range="-180.0000 180.0000" />
                      <geom type="box" pos="-0.0080 -0.0468 -0.0009" size="0.0553 0.0577 0.0166" quat="1.0000 0.0000 0.0000 0.0000" density="1000" />
                    </body>
                  </body>
                </body>
              </body>
            </body>
          </body>
        </body>
      </body>
    </body>
  </worldbody>
  <actuator>
    <motor name="L_Hip_x" joint="L_Hip_x" gear="500" />
    <motor name="L_Hip_y" joint="L_Hip_y" gear="500" />
    <motor name="L_Hip_z" joint="L_Hip_z" gear="500" />
    <motor name="L_Knee_x" joint="L_Knee_x" gear="500" />
    <motor name="L_Knee_y" joint="L_Knee_y" gear="500" />
    <motor name="L_Knee_z" joint="L_Knee_z" gear="500" />
    <motor name="L_Ankle_x" joint="L_Ankle_x" gear="500" />
    <motor name="L_Ankle_y" joint="L_Ankle_y" gear="500" />
    <motor name="L_Ankle_z" joint="L_Ankle_z" gear="500" />
    <motor name="L_Toe_x" joint="L_Toe_x" gear="500" />
    <motor name="L_Toe_y" joint="L_Toe_y" gear="500" />
    <motor name="L_Toe_z" joint="L_Toe_z" gear="500" />
    <motor name="R_Hip_x" joint="R_Hip_x" gear="500" />
    <motor name="R_Hip_y" joint="R_Hip_y" gear="500" />
    <motor name="R_Hip_z" joint="R_Hip_z" gear="500" />
    <motor name="R_Knee_x" joint="R_Knee_x" gear="500" />
    <motor name="R_Knee_y" joint="R_Knee_y" gear="500" />
    <motor name="R_Knee_z" joint="R_Knee_z" gear="500" />
    <motor name="R_Ankle_x" joint="R_Ankle_x" gear="500" />
    <motor name="R_Ankle_y" joint="R_Ankle_y" gear="500" />
    <motor name="R_Ankle_z" joint="R_Ankle_z" gear="500" />
    <motor name="R_Toe_x" joint="R_Toe_x" gear="500" />
    <motor name="R_Toe_y" joint="R_Toe_y" gear="500" />
    <motor name="R_Toe_z" joint="R_Toe_z" gear="500" />
    <motor name="Torso_x" joint="Torso_x" gear="500" />
    <motor name="Torso_y" joint="Torso_y" gear="500" />
    <motor name="Torso_z" joint="Torso_z" gear="500" />
    <motor name="Spine_x" joint="Spine_x" gear="500" />
    <motor name="Spine_y" joint="Spine_y" gear="500" />
    <motor name="Spine_z" joint="Spine_z" gear="500" />
    <motor name="Chest_x" joint="Chest_x" gear="500" />
    <motor name="Chest_y" joint="Chest_y" gear="500" />
    <motor name="Chest_z" joint="Chest_z" gear="500" />
    <motor name="Neck_x" joint="Neck_x" gear="500" />
    <motor name="Neck_y" joint="Neck_y" gear="500" />
    <motor name="Neck_z" joint="Neck_z" gear="500" />
    <motor name="Head_x" joint="Head_x" gear="500" />
    <motor name="Head_y" joint="Head_y" gear="500" />
    <motor name="Head_z" joint="Head_z" gear="500" />
    <motor name="L_Thorax_x" joint="L_Thorax_x" gear="500" />
    <motor name="L_Thorax_y" joint="L_Thorax_y" gear="500" />
    <motor name="L_Thorax_z" joint="L_Thorax_z" gear="500" />
    <motor name="L_Shoulder_x" joint="L_Shoulder_x" gear="500" />
    <motor name="L_Shoulder_y" joint="L_Shoulder_y" gear="500" />
    <motor name="L_Shoulder_z" joint="L_Shoulder_z" gear="500" />
    <motor name="L_Elbow_x" joint="L_Elbow_x" gear="500" />
    <motor name="L_Elbow_y" joint="L_Elbow_y" gear="500" />
    <motor name="L_Elbow_z" joint="L_Elbow_z" gear="500" />
    <motor name="L_Wrist_x" joint="L_Wrist_x" gear="500" />
    <motor name="L_Wrist_y" joint="L_Wrist_y" gear="500" />
    <motor name="L_Wrist_z" joint="L_Wrist_z" gear="500" />
    <motor name="L_Hand_x" joint="L_Hand_x" gear="500" />
    <motor name="L_Hand_y" joint="L_Hand_y" gear="500" />
    <motor name="L_Hand_z" joint="L_Hand_z" gear="500" />
    <motor name="R_Thorax_x" joint="R_Thorax_x" gear="500" />
    <motor name="R_Thorax_y" joint="R_Thorax_y" gear="500" />
    <motor name="R_Thorax_z" joint="R_Thorax_z" gear="500" />
    <motor name="R_Shoulder_x" joint="R_Shoulder_x" gear="500" />
    <motor name="R_Shoulder_y" joint="R_Shoulder_y" gear="500" />
    <motor name="R_Shoulder_z" joint="R_Shoulder_z" gear="500" />
    <motor name="R_Elbow_x" joint="R_Elbow_x" gear="500" />
    <motor name="R_Elbow_y" joint="R_Elbow_y" gear="500" />
    <motor name="R_Elbow_z" joint="R_Elbow_z" gear="500" />
    <motor name="R_Wrist_x" joint="R_Wrist_x" gear="500" />
    <motor name="R_Wrist_y" joint="R_Wrist_y" gear="500" />
    <motor name="R_Wrist_z" joint="R_Wrist_z" gear="500" />
    <motor name="R_Hand_x" joint="R_Hand_x" gear="500" />
    <motor name="R_Hand_y" joint="R_Hand_y" gear="500" />
    <motor name="R_Hand_z" joint="R_Hand_z" gear="500" />
  </actuator>
  <contact>
    <exclude body1="Torso" body2="Chest" />
    <exclude body1="Head" body2="Chest" />
    <exclude body1="R_Knee" body2="R_Toe" />
    <exclude body1="R_Knee" body2="L_Ankle" />
    <exclude body1="R_Knee" body2="L_Toe" />
    <exclude body1="L_Knee" body2="L_Toe" />
    <exclude body1="L_Knee" body2="R_Ankle" />
    <exclude body1="L_Knee" body2="R_Toe" />
    <exclude body1="L_Shoulder" body2="Chest" />
    <exclude body1="R_Shoulder" body2="Chest" />
  </contact>
  <sensor />
  <size njmax="700" nconmax="700" />
</mujoco>